Workbook
Name TABLAPD: 'PUNT-DIRECTA'!$B$3:$AB$33
Name TABLAPER: PERCENTIL2!$A$3:$Z$119

Sheet APLICACION
B9: Nombre :Estefania Milagros Negron Huapaya
A11: Instrucciones: La persona deberá responder las afirmaciones con una "1" en la casilla correspondiente. Elegirá la opción de "Verdadero" " casilla izquierda. Elegirá la opción de "Falso" casilla derecha. Trate de marcar cada frase aún cuando no está seguro de su decisión. Si ha intentado y todavía no se puede decidir, marque el Falso. Procure no hacer dobles respuestas.
A12: ITEMS | D12: V | E12: F
A13: 1 | B13: Ultimamente parece que me quedo sin fuerzas incluso por las mañanas. | C13: 1 | E13: 1 | AG13: 1
A14: 2 | B14: Siempre me aseguro de que mi trabajo esté bien planeado y organizado. | C14: 2 | D14: 1
A15: 3 | B15: Disfruto haciendo tantas cosas diferentes que no puedo decidir por cuál empezar. | C15: 3 | E15: 1
A16: 4 | B16: Me preocupa que las personas de las que dependo me abandonen. | C16: 4 | E16: 1
A17: 5 | B17: Aunque me da miedo hacer amistades, me gustaría tener más de las que tengo. | C17: 5 | E17: 1 | F17: =(2*(D18+D27+D55+D102+D131+D151+D161+D192)+D29+D36+D42+D82+D104+E166+D202) -> 6
A18: 6 | B18: Raramente exteriorizo los pocos sentimientos que tengo. | C18: 6 | E18: 1 | F18: =(2*(D17+D24+D38+D111+D147+D207)+(D35+D36+D58+D64+E79+D104+D105+D124+E166+D190+D196+D205)) -> 1
A19: 7 | B19: Me cuesta mantener el equilibrio cuando camino. | C19: 7 | E19: 1 | F19: =(2*(D35+D63+D83+D105+D123+D181+D187+D196+D205)+(D29+D34+D51+E65+D71+D82+D102+D138+D182+D190)) -> 6
A20: 8 | B20: Siempre busco oportunidades nuevas que me resulten emocionantes. | C20: 8 | D20: 1 | F20: =(2*(D16+D54+D72+D89+D121+D145+D174+D185+D206)+(D17+D35+E79+D84+D187)) -> 6
A21: 9 | B21: Algunas veces puedo ser bastante duro y desagradable con mi familia | C21: 9 | E21: 1 | F21: =(2*(D22+D42+D58+D96+D129+D166+D183)+E18+D20+E27+E36+E38+D87+E151+D167+E190+E207) -> 15
A22: 10 | B22: Me gusta ser el centro de atención. | C22: 10 | E22: 1 | F22: =(2*(D20+D32+D65+D87+D141+D167+D186+D197)+(E38+D42+D58+D79+D96+E132+D154+D166+D190)) -> 22
A23: 11 | B23: De adolescente tuve muchos problemas por mi mal comportamiento en la escuela o instituto. | C23: 11 | E23: 1 | F23: =(2*(D41+D50+D66+D79+D99+D118+D144+D154+D171+D201)+(D22+D31+D95+D129+D183+D203)) -> 6
A24: 12 | B24: Me da miedo hacerme muy amigo de alquien por que podría acabar sintiéndome ridiculizado o avergonzado. | C24: 12 | E24: 1 | F24: =(2*(D23+D31+D77+D95+D159+D195+D203)+(D48+D50+E60+D117+D164+E170+D171)) -> 1
A25: 13 | B25: Noto que la gente está hablando de mí cuando paso a su lado. | C25: 13 | E25: 1 | F25: =(2*(D21+D62+D78+D109+D115+D127+D153+D164)+(D23+D28+D33+D86+D157+D184)) -> 1
A26: 14 | B26: Hace uno años comencé a sentirme un fracasado. | C26: 14 | E26: 1 | F26: =(2*(D14+D47+D60+D75+D85+D140+D152+D170+D191+D200)+(E95+E159+E164)) -> 13
A27: 15 | B27: Si puedo elegir, prefiero hacer las cosas solo. | C27: 15 | D27: 1 | F27: =(2*(D29+D44+D94+D108+D134+D149+D179+D199)+(D33+D49+D64+D91+D100+D109+D112+D180+D184+D196)) -> 9
A28: 16 | B28: Últimamente he comenzado a sentir deseos de destrozar cosas. | C28: 16 | E28: 1 | F28: =(2*(D51+D71+D97+D112+D138+D178+D204)+(D16+D24+E32+D35+D82+E87+D105+D168+D176+D190+D207)) -> 5
A29: 17 | B29: Las cosas que hoy van bien no durarán mucho tiempo. | C29: 17 | E29: 1 | F29: =(2*(D25+D36+D56+D104+D124+D168+D177+D202)+(D30+D70+D82+D102+D105+D133+D135+D138+D160+D175+D179+D184+D207)) -> 2
A30: 18 | B30: A veces, cuando las cosas empiezan a irme mal, me siento como si estuviera loco o fuera de la realidad. | C30: 18 | E30: 1 | F30: =(2*(D28+D30+D49+D82+D146+D176+D190)+(D16+D71+D92+D94+D105+D112+D123+D138+D149+D168+D178+D204+D205)) -> 6
A31: 19 | B31: Hago lo que quiero sin preocuparme de las consecuencias que tenga en los demás. | C31: 19 | E31: 1 | F31: =(2*(D33+D64+D91+D100+D116+D148+D165+D184)+(D25+D36+D80+D108+D160+D179+D192+D207)) -> 9
A32: 20 | B32: Afronto mis actividades diarias con mucha energía y persistencia. | C32: 20 | D32: 1
A33: 21 | B33: Nunca perdono una ofensa ni olvido una situación embarazosa que alguien me haya causado. | C33: 21 | D33: 1
A34: 22 | B34: Me siento extremadamente deprimido y triste gran parte del tiempo. | C34: 22 | E34: 1
A35: 23 | B35: Siempre tiendo a culparme cuando las cosas van mal. | C35: 23 | E35: 1 | F35: =(2*(D45+D84+D101+D125+D135+D155)+(D43+D53+D56+D63+D103+D120+D121)) -> 2
A36: 24 | B36: Hace mucho decidí que es mejor tener poca relación con la gente. | C36: 24 | E36: 1 | F36: =(2*(D19+D40+D53+D132+D158)+(D13+E32+D69+D125+D130)) -> 0
A37: 25 | B37: Tengo un problema con el alcohol que nos ha creado dificultades a mí y a mi familia. | C37: 25 | E37: 1 | F37: =(2*(D15+D39+D68+D120+D175+D189)+(D49+D62+D66+D94+D95+D117+D167)) -> 3
A38: 26 | B38: Soy una persona socialmente muy reservada y tímida. | C38: 26 | E38: 1 | F38: =(2*(D26+D46+D76+D130+D163+D182)+(D29+D40+D51+D63+D83+E87+D89+D97+D105+D113+D123+D126+D132+D190+D205)) -> 6
A39: 27 | B39: Muchas veces me siento muy alegre y animado sin ninguna razón. | C39: 27 | E39: 1 | F39: =(2*(D37+D57+D106+D142+D173)+(D77+D95+D138)) -> 0
A40: 28 | B40: En las últimas semanas me he sentido agotado sin ningún motivo en particular. | C40: 28 | E40: 1 | F40: =(2*(D48+D73+D93+D117+D128+D136+D156)+(D23+D77+D164+D170)) -> 0
A41: 29 | B41: Mi tiempo es más valioso que el de los demás. | C41: 29 | E41: 1 | F41: =(2*(D74+D88+D103+D137+D162)+(D56+D59+D69+D86+D101+D122+D125+D155+D169)) -> 4
A42: 30 | B42: Siempre estoy buscando hacer nuevas amistades y conocer gente nueva. | C42: 30 | D42: 1 | F42: =(2*(D45+D70+D92+D133+D143+D150)+(D30+D36+D64+D94+D101+D104+D107+D116+D135+D148+D160+D168+D177+D184+D194)) -> 6
A43: 31 | B43: Desde hace unas semanas estoy muy nervioso. | C43: 31 | E43: 1 | F43: =(2*(D13+D34+D69+D90+D113+D119+D126)+(D40+D53+D71+D76+D82+D92+D123+D130+D132+D182)) -> 6
A44: 32 | B44: Simplemente, no he tenido la suerte que otras personas han tenido en la vida. | C44: 32 | D44: 1 | F44: =(2*(D80+D107+D139+D160+D194)+(D25+D66+D91+D100+D124+D133+D148+D184+D201)) -> 2
A45: 33 | B45: Las ideas me dan vueltas en la cabeza una y otra vez y no desaparecen. | C45: 33 | D45: 1 | F45: Validez
A46: 34 | B46: Desde hace uno o dos años, al pensar sobre la vida, me siento muy triste y desanimado. | C46: 34 | E46: 1 | F46: =D61+D110+D172 -> 1
A47: 35 | B47: Intento hacerlo todo tan perfecto como sea posible. | C47: 35 | D47: 1
A48: 36 | B48: Mi adicción a las drogas hizo que faltara al trabajo. | C48: 36 | E48: 1 | F48: 22-170 | H48: 125-143 | J48: 47-157 | L48: 40 - 181 | N48: 81 - 116 | P48: 85-116 | R48: 76-150 | T48: 25-94 | V48: 44 -121
A49: 37 | B49: Mi estado de ánimo varía mucho de un día para otro. | C49: 37 | E49: 1 | F49: =D34+D182 -> 1 | G49: =E34+E182 -> 1 | H49: =D137+D155 -> 1 | I49: =E137+E155 -> 1 | J49: =D59+D169 -> 2 | K49: =E59+E169 -> 0 | L49: =D52+D193 -> 0 | M49: =E52+E193 -> 2 | N49: =D93+D128 -> 0 | O49: =E93+E128 -> 2 | P49: =D97+D138 -> 1 | Q49: =E97+E138 -> 1 | R49: =D88+D162 -> 0 | S49: =E88+E162 -> 2 | T49: =D37+D106 -> 0 | U49: =E37+E106 -> 2 | V49: =D56+D133 -> 0 | W49: =E56+E133 -> 2
...

Sheet RESULTADOS 
P5: =APLICACION!B9 -> Nombre :Estefania Milagros Negron Huapaya
B9: ESCALA DE VALIDEZ | C9: Escalas de Validez | D9: PD
B10: V | C10: Invalidez | D10: =APLICACION!F46 -> 1 | O10: ='Interpretacion '!R8 -> válido pero dudable, cuestionable.
B11: W | C11: Inconsistencia | D11: =APLICACION!K60 -> 7 | O11: ='Interpretacion '!R9 -> consistente.
B12: X | C12: Sinceridad | D12: =VLOOKUP(K12,RESULTADOS!A3:B117,2,FALSE) -> 30 | K12: =APLICACION!G63 -> 26 | O12: ='Interpretacion '!R10 -> clínicamente interpretable
B13: Y | C13: Deseabilidad Social | D13: =VLOOKUP(K13,RESULTADOS!A3:C27,3,FALSE) -> 78 | K13: =APLICACION!G64 -> 18 | O13: ='Interpretacion '!R11 -> Tendencia a parecer socialmente agradable, moralmente admirable o emocionalmente equilibrado. Tendencia a mostrar una imagen de sí mismo positiva e interesante. Cuanto más alta sea la puntuación, más probable es que el paciente haya ocultado ciertos aspectos de sus dificultades psicológicas o interpersonales.
B14: Z | C14: Devaluación | D14: =VLOOKUP('RESULTADOS '!K14,RESULTADOS!A3:D33,4,FALSE) -> 37 | K14: =APLICACION!G65 -> 4 | O14: ='Interpretacion '!R12 -> Tendencia del sujeto a menospreciarse o subestimarse manifestando más problemas emocionales y perso¬nales de los que un análisis posterior pueda reflejar.
B16: Patrones de Personalidad | D16: PE | H16: PERCENTIL | L16: PD
B17: 1 | C17: Esquizoide | D17: =CORRECCION!D17 -> 40 | E17: 3 | G17: 2 | H17: =IFERROR(VLOOKUP(D17,TABLAPER,G17,FALSE),"") -> 31 | L17: =APLICACION!F17 -> 6 | O17: =CORRECCION!O17 -> No presenta
B18: 2A | C18: Evitativo | D18: =CORRECCION!D18 -> 6 | E18: 4 | G18: 3 | H18: =IFERROR(VLOOKUP(D18,TABLAPER,G18,FALSE),"") -> 5 | L18: =APLICACION!F18 -> 1 | O18: =CORRECCION!O18 -> No presenta
B19: 2B | C19: Melancólico | D19: =CORRECCION!D19 -> 30 | E19: 5 | G19: 4 | H19: =IFERROR(VLOOKUP(D19,TABLAPER,G19,FALSE),"") -> 28 | L19: =APLICACION!F19 -> 6 | O19: =CORRECCION!O19 -> No presenta
B20: 3 | C20: Dependiente | D20: =CORRECCION!D20 -> 36 | E20: 6 | G20: 5 | H20: =IFERROR(VLOOKUP(D20,TABLAPER,G20,FALSE),"") -> 25 | L20: =APLICACION!F20 -> 6 | O20: =CORRECCION!O20 -> No presenta
B21: 4A | C21: Histriónico | D21: =CORRECCION!D21 -> 75 | E21: 7 | G21: 6 | H21: =IFERROR(VLOOKUP(D21,TABLAPER,G21,FALSE),"") -> 83 | L21: =APLICACION!F21 -> 15 | O21: =CORRECCION!O21 -> Patrones menos adaptativos y Trastornos
B22: 4B | C22: Tempestuoso | D22: =CORRECCION!D22 -> 80 | E22: 8 | G22: 7 | H22: =IFERROR(VLOOKUP(D22,TABLAPER,G22,FALSE),"") -> 93 | L22: =APLICACION!F22 -> 22
B23: 5 | C23: Narcisista | D23: =CORRECCION!D23 -> 62 | E23: 9 | G23: 8 | H23: =IFERROR(VLOOKUP(D23,TABLAPER,G23,FALSE),"") -> 56 | L23: =APLICACION!F23 -> 6 | O23: =CORRECCION!O23 -> Categoría de Riesgo
B24: 6A | C24: Antisocial | D24: =CORRECCION!D24 -> 20 | E24: 10 | G24: 9 | H24: =IFERROR(VLOOKUP(D24,TABLAPER,G24,FALSE),"") -> 25 | L24: =APLICACION!F24 -> 1 | O24: =CORRECCION!O24 -> No presenta
B25: 6B | C25: Sádico | D25: =CORRECCION!D25 -> 10 | E25: 11 | G25: 10 | H25: =IFERROR(VLOOKUP(D25,TABLAPER,G25,FALSE),"") -> 13 | L25: =APLICACION!F25 -> 1 | O25: =CORRECCION!O25 -> No presenta
B26: 7 | C26: Compulsivo | D26: =CORRECCION!D26 -> 49 | E26: 12 | G26: 11 | H26: =IFERROR(VLOOKUP(D26,TABLAPER,G26,FALSE),"") -> 26 | L26: =APLICACION!F26 -> 13 | O26: =CORRECCION!O26 -> No presenta
B27: 8A | C27: Negativista | D27: =CORRECCION!D27 -> 60 | E27: 13 | G27: 12 | H27: =IFERROR(VLOOKUP(D27,TABLAPER,G27,FALSE),"") -> 48 | L27: =APLICACION!F27 -> 9 | O27: =CORRECCION!O27 -> No presenta
B28: 8B | C28: Masoquista | D28: =CORRECCION!D28 -> 38 | E28: 14 | G28: 13 | H28: =IFERROR(VLOOKUP(D28,TABLAPER,G28,FALSE),"") -> 33 | L28: =APLICACION!F28 -> 5 | O28: =CORRECCION!O28 -> No presenta
B29: Patologías Graves Personalidad | D29: =CORRECCION!D29 -> PE | H29: PERCENTIL | L29: PD
B30: S | C30: Esquizotípico | D30: =CORRECCION!D30 -> 12 | E30: 15 | G30: 14 | H30: =IFERROR(VLOOKUP(D30,TABLAPER,G30,FALSE),"") -> 14 | L30: =APLICACION!F29 -> 2 | O30: =CORRECCION!O30 -> No presenta
B31: C | C31: Límite | D31: =CORRECCION!D31 -> 45 | E31: 16 | G31: 15 | H31: =IFERROR(VLOOKUP(D31,TABLAPER,G31,FALSE),"") -> 40 | L31: =APLICACION!F30 -> 6 | O31: =CORRECCION!O31 -> No presenta
B32: P | C32: Paranoide | D32: =CORRECCION!D32 -> 66 | E32: 17 | G32: 16 | H32: =IFERROR(VLOOKUP(D32,TABLAPER,G32,FALSE),"") -> 62 | L32: =APLICACION!F31 -> 9 | O32: =CORRECCION!O32 -> Categoría de Riesgo
D33: =CORRECCION!D33 -> 0 | O33: =CORRECCION!O33 -> No presenta
B34: Sindromes Clínicos | D34: =CORRECCION!D34 -> PE | H34: PERCENTIL | L34: PD
B35: A | C35: Ansiedad Generalizada | D35: =CORRECCION!D35 -> 15 | E35: 18 | G35: 17 | H35: =IFERROR(VLOOKUP(D35,TABLAPER,G35,FALSE),"") -> 14 | L35: =APLICACION!F35 -> 2 | O35: =CORRECCION!O35 -> No presenta
B36: H | C36: Síntomas Somáticos | D36: =CORRECCION!D36 -> 0 | E36: 19 | G36: 18 | H36: =IFERROR(VLOOKUP(D36,TABLAPER,G36,FALSE),"") -> 11 | L36: =APLICACION!F36 -> 0 | O36: =CORRECCION!O36 -> No presenta
B37: N | C37: Espectro Bípolar | D37: =CORRECCION!D37 -> 30 | E37: 20 | G37: 19 | H37: =IFERROR(VLOOKUP(D37,TABLAPER,G37,FALSE),"") -> 22 | L37: =APLICACION!F37 -> 3 | O37: =CORRECCION!O37 -> No presenta
B38: D | C38: Depresión Persistente | D38: =CORRECCION!D38 -> 30 | E38: 21 | G38: 20 | H38: =IFERROR(VLOOKUP(D38,TABLAPER,G38,FALSE),"") -> 28 | L38: =APLICACION!F38 -> 6 | O38: =CORRECCION!O38 -> No presenta
B39: B | C39: Consumo de Alcohol | D39: =CORRECCION!D39 -> 0 | E39: 22 | G39: 21 | H39: =IFERROR(VLOOKUP(D39,TABLAPER,G39,FALSE),"") -> 34 | L39: =APLICACION!F39 -> 0 | O39: =CORRECCION!O39 -> No presenta
B40: T | C40: Consumo de Drogas | D40: =CORRECCION!D40 -> 0 | E40: 23 | G40: 22 | H40: =IFERROR(VLOOKUP(D40,TABLAPER,G40,FALSE),"") -> 24 | L40: =APLICACION!F40 -> 0 | O40: =CORRECCION!O40 -> No presenta
B41: R | C41: Estrés Postraumático | D41: =CORRECCION!D41 -> 48 | E41: 24 | G41: 23 | H41: =IFERROR(VLOOKUP(D41,TABLAPER,G41,FALSE),"") -> 42 | L41: =APLICACION!F41 -> 4 | O41: =CORRECCION!O41 -> No presenta
B42: SS | C42: Espectro Esquizofrénico | D42: =CORRECCION!D42 -> 40 | E42: 25 | G42: 24 | H42: =IFERROR(VLOOKUP(D42,TABLAPER,G42,FALSE),"") -> 33 | L42: =APLICACION!F42 -> 6 | O42: =CORRECCION!O42 -> No presenta
B43: CC | C43: Depresión Mayor | D43: =CORRECCION!D43 -> 51 | E43: 26 | G43: 25 | H43: =IFERROR(VLOOKUP(D43,TABLAPER,G43,FALSE),"") -> 46 | L43: =APLICACION!F43 -> 6 | O43: =CORRECCION!O43 -> No presenta
B44: PP | C44: Delirante | D44: =CORRECCION!D44 -> 60 | E44: 27 | G44: 26 | H44: =IFERROR(VLOOKUP(D44,TABLAPER,G44,FALSE),"") -> 51 | L44: =APLICACION!F44 -> 2 | O44: =CORRECCION!O44 -> No presenta

Sheet FACETAS GROSSMAN Y RESPUESTAS S
A8: Patrones de Personalidad | C8: PD | D8: PE | G8: Respuestas Siginificativas | I8: PD | J8: %
A9: 1 | B9: Esquizoide | D9: =CORRECCION!D17 -> 40 | E9: =REPT("g",D9/2) -> gggggggggggggggggggg | G9: 1 | H9: TDAH | I9: ='RPTA SIGNIFICATIVAS'!C9 -> 2 | J9: ='RPTA SIGNIFICATIVAS'!D9 -> 0.33333333
A10: 1.1 | B10: Interpersonalmente Desvinculado | C10: =APLICACION!D24+APLICACION!D27+APLICACION!D36+APLICACION!D116+APLICACION!D161+APLICACION!E166+APLICACION!D192+APLICACION!E197+APLICACION!D202 -> 1 | D10: =IF(C10=0,'PERCENTIL GROSSMAN'!B3,IF(C10=1,'PERCENTIL GROSSMAN'!D3,IF(C10=2,'PERCENTIL GROSSMAN'!F3,IF(C10=3,'PERCENTIL GROSSMAN'!H3,IF(C10=4,'PERCENTIL GROSSMAN'!J3,IF(C10=5,'PERCENTIL GROSSMAN'!L3,IF(C10=6,'PERCENTIL GROSSMAN'!N3,IF(C10=7,'PERCENTIL GROSSMAN'!P3,IF(C10=8,'PERCENTIL GROSSMAN'!R3,IF(C10=9,'PERCENTIL GROSSMAN'!T3)))))))))) -> 20 | E10: =REPT("g",D10/2) -> gggggggggg | G10: 2 | H10: Espectro Autista | I10: ='RPTA SIGNIFICATIVAS'!C10 -> 0 | J10: ='RPTA SIGNIFICATIVAS'!D10 -> 0
A11: 1.2 | B11: Contenido Escaso | C11: =APLICACION!D38+APLICACION!E42+APLICACION!E58+APLICACION!E79+APLICACION!D111+APLICACION!D151+APLICACION!D187+APLICACION!E190+APLICACION!D207 -> 2 | D11: =IF(C11=0,'PERCENTIL GROSSMAN'!B4,IF(C11=1,'PERCENTIL GROSSMAN'!D4,IF(C11=2,'PERCENTIL GROSSMAN'!F4,IF(C11=3,'PERCENTIL GROSSMAN'!H4,IF(C11=4,'PERCENTIL GROSSMAN'!J4,IF(C11=5,'PERCENTIL GROSSMAN'!L4,IF(C11=6,'PERCENTIL GROSSMAN'!N4,IF(C11=7,'PERCENTIL GROSSMAN'!P4,IF(C11=8,'PERCENTIL GROSSMAN'!R4,IF(C11=9,'PERCENTIL GROSSMAN'!T4)))))))))) -> 30 | E11: =REPT("g",D11/2) -> ggggggggggggggg | G11: 3 | H11: Maltrato Infantil | I11: ='RPTA SIGNIFICATIVAS'!C11 -> 2 | J11: ='RPTA SIGNIFICATIVAS'!D11 -> 1
A12: 1.3 | B12: Temperalmente apático | C12: =APLICACION!D39+APLICACION!E43+APLICACION!E59+APLICACION!E80+APLICACION!D112+APLICACION!D152+APLICACION!D188+APLICACION!E191+APLICACION!D208 -> 3 | D12: =IF(C12=0,'PERCENTIL GROSSMAN'!B5,IF(C12=1,'PERCENTIL GROSSMAN'!D5,IF(C12=2,'PERCENTIL GROSSMAN'!F5,IF(C12=3,'PERCENTIL GROSSMAN'!H5,IF(C12=4,'PERCENTIL GROSSMAN'!J5,IF(C12=5,'PERCENTIL GROSSMAN'!L5,IF(C12=6,'PERCENTIL GROSSMAN'!N5,IF(C12=7,'PERCENTIL GROSSMAN'!P5,IF(C12=8,'PERCENTIL GROSSMAN'!R5,IF(C12=9,'PERCENTIL GROSSMAN'!T5)))))))))) -> 60 | E12: =REPT("g",D12/2) -> gggggggggggggggggggggggggggggg | G12: 4 | H12: Trastornos de la conducta alimentaria | I12: ='RPTA SIGNIFICATIVAS'!C12 -> 0 | J12: ='RPTA SIGNIFICATIVAS'!D12 -> 0
A13: 2A | B13: Evitativo | D13: =CORRECCION!D18 -> 6 | E13: =REPT("g",D13/2) -> ggg | G13: 5 | H13: Falta de Control Emocional | I13: ='RPTA SIGNIFICATIVAS'!C13 -> 1 | J13: ='RPTA SIGNIFICATIVAS'!D13 -> 0.125
A14: 2A.1 | B14: Interpersonalmente Aversivo | C14: =APLICACION!D27+APLICACION!D38+APLICACION!E42+APLICACION!E58+APLICACION!E96+APLICACION!D111+APLICACION!D151+APLICACION!E166 -> 2 | D14: =IF(C14=0,'PERCENTIL GROSSMAN'!B6,IF(C14=1,'PERCENTIL GROSSMAN'!D6,IF(C14=2,'PERCENTIL GROSSMAN'!F6,IF(C14=3,'PERCENTIL GROSSMAN'!H6,IF(C14=4,'PERCENTIL GROSSMAN'!J6,IF(C14=5,'PERCENTIL GROSSMAN'!L6,IF(C14=6,'PERCENTIL GROSSMAN'!N6,IF(C14=7,'PERCENTIL GROSSMAN'!P6,IF(C14=8,'PERCENTIL GROSSMAN'!R6,IF(C14=9,'PERCENTIL GROSSMAN'!T6)))))))))) -> 30 | E14: =REPT("g",D14/2) -> ggggggggggggggg | G14: 6 | H14: Explosiones de Ira | I14: ='RPTA SIGNIFICATIVAS'!C14 -> 0 | J14: ='RPTA SIGNIFICATIVAS'!D14 -> 0
A15: 2A.2 | B15: Autoimagen Alienada | C15: =APLICACION!D35+APLICACION!D70+APLICACION!E79+APLICACION!D123+APLICACION!D147+APLICACION!D168+APLICACION!D190+APLICACION!D204+APLICACION!D205 -> 2 | D15: =IF(C15=0,'PERCENTIL GROSSMAN'!B7,IF(C15=1,'PERCENTIL GROSSMAN'!D7,IF(C15=2,'PERCENTIL GROSSMAN'!F7,IF(C15=3,'PERCENTIL GROSSMAN'!H7,IF(C15=4,'PERCENTIL GROSSMAN'!J7,IF(C15=5,'PERCENTIL GROSSMAN'!L7,IF(C15=6,'PERCENTIL GROSSMAN'!N7,IF(C15=7,'PERCENTIL GROSSMAN'!P7,IF(C15=8,'PERCENTIL GROSSMAN'!R7,IF(C15=9,'PERCENTIL GROSSMAN'!T7)))))))))) -> 30 | E15: =REPT("g",D15/2) -> ggggggggggggggg | G15: 7 | H15: Preocupación por su salud | I15: ='RPTA SIGNIFICATIVAS'!C15 -> 0 | J15: ='RPTA SIGNIFICATIVAS'!D15 -> 0
A16: 2A.3 | B16: Contenido Vejatorio | C16: =APLICACION!E17+APLICACION!D24+APLICACION!D36+APLICACION!D64+APLICACION!D104+APLICACION!D105+APLICACION!D124+APLICACION!D196+APLICACION!D207 -> 2 | D16: =IF(C16=0,'PERCENTIL GROSSMAN'!B8,IF(C16=1,'PERCENTIL GROSSMAN'!D8,IF(C16=2,'PERCENTIL GROSSMAN'!F8,IF(C16=3,'PERCENTIL GROSSMAN'!H8,IF(C16=4,'PERCENTIL GROSSMAN'!J8,IF(C16=5,'PERCENTIL GROSSMAN'!L8,IF(C16=6,'PERCENTIL GROSSMAN'!N8,IF(C16=7,'PERCENTIL GROSSMAN'!P8,IF(C16=8,'PERCENTIL GROSSMAN'!R8,IF(C16=9,'PERCENTIL GROSSMAN'!T8)))))))))) -> 40 | E16: =REPT("g",D16/2) -> gggggggggggggggggggg | G16: 8 | H16: Alienación Interpersonal | I16: ='RPTA SIGNIFICATIVAS'!C16 -> 0 | J16: ='RPTA SIGNIFICATIVAS'!D16 -> 0
A17: 2B | B17: Melancólico | D17: =CORRECCION!D19 -> 30 | E17: =REPT("g",D17/2) -> ggggggggggggggg | G17: 9 | H17: Abuso de Medicación | I17: ='RPTA SIGNIFICATIVAS'!C17 -> 0 | J17: ='RPTA SIGNIFICATIVAS'!D17 -> 0
A18: 2B.1 | B18: Cognitivamente Fatalista | C18: =APLICACION!D29+APLICACION!D35+APLICACION!D45+APLICACION!D63+APLICACION!D64+APLICACION!D83+APLICACION!D101+APLICACION!D138+APLICACION!D196 -> 3 | D18: =IF(C18=0,'PERCENTIL GROSSMAN'!B9,IF(C18=1,'PERCENTIL GROSSMAN'!D9,IF(C18=2,'PERCENTIL GROSSMAN'!F9,IF(C18=3,'PERCENTIL GROSSMAN'!H9,IF(C18=4,'PERCENTIL GROSSMAN'!J9,IF(C18=5,'PERCENTIL GROSSMAN'!L9,IF(C18=6,'PERCENTIL GROSSMAN'!N9,IF(C18=7,'PERCENTIL GROSSMAN'!P9,IF(C18=8,'PERCENTIL GROSSMAN'!R9,IF(C18=9,'PERCENTIL GROSSMAN'!T9)))))))))) -> 30 | E18: =REPT("g",D18/2) -> ggggggggggggggg | G18: 10 | H18: Potencial Conducta autodestructiva | I18: ='RPTA SIGNIFICATIVAS'!C18 -> 2 | J18: ='RPTA SIGNIFICATIVAS'!D18 -> 0.16666667
A19: 2B.2 | B19: Autoimagen Inutil | C19: =APLICACION!D51+APLICACION!D71+APLICACION!D105+APLICACION!D124+APLICACION!D181+APLICACION!D187+APLICACION!D190+APLICACION!D204+APLICACION!D207 -> 1 | D19: =IF(C19=0,'PERCENTIL GROSSMAN'!B10,IF(C19=1,'PERCENTIL GROSSMAN'!D10,IF(C19=2,'PERCENTIL GROSSMAN'!F10,IF(C19=3,'PERCENTIL GROSSMAN'!H10,IF(C19=4,'PERCENTIL GROSSMAN'!J10,IF(C19=5,'PERCENTIL GROSSMAN'!L10,IF(C19=6,'PERCENTIL GROSSMAN'!N10,IF(C19=7,'PERCENTIL GROSSMAN'!P10,IF(C19=8,'PERCENTIL GROSSMAN'!R10,IF(C19=9,'PERCENTIL GROSSMAN'!T10)))))))))) -> 30 | E19: =REPT("g",D19/2) -> ggggggggggggggg | G19: 11 | H19: Conductas/Tendencias Autolesivas | I19: ='RPTA SIGNIFICATIVAS'!C19 -> 0 | J19: ='RPTA SIGNIFICATIVAS'!D19 -> 0
A20: 2B.3 | B20: Temperalmente Afligido | C20: =APLICACION!D34+APLICACION!E65+APLICACION!D82+APLICACION!D102+APLICACION!D113+APLICACION!D119+APLICACION!D123+APLICACION!D182+APLICACION!D205 -> 4 | D20: =IF(C20=0,'PERCENTIL GROSSMAN'!B11,IF(C20=1,'PERCENTIL GROSSMAN'!D11,IF(C20=2,'PERCENTIL GROSSMAN'!F11,IF(C20=3,'PERCENTIL GROSSMAN'!H11,IF(C20=4,'PERCENTIL GROSSMAN'!J11,IF(C20=5,'PERCENTIL GROSSMAN'!L11,IF(C20=6,'PERCENTIL GROSSMAN'!N11,IF(C20=7,'PERCENTIL GROSSMAN'!P11,IF(C20=8,'PERCENTIL GROSSMAN'!R11,IF(C20=9,'PERCENTIL GROSSMAN'!T11)))))))))) -> 75 | E20: =REPT("g",D20/2) -> ggggggggggggggggggggggggggggggggggggg | G20: 12 | H20: Lesión Cerebral | I20: ='RPTA SIGNIFICATIVAS'!C20 -> 0 | J20: ='RPTA SIGNIFICATIVAS'!D20 -> 0
A21: 3 | B21: Dependiente | D21: =CORRECCION!D20 -> 36 | E21: =REPT("g",D21/2) -> gggggggggggggggggg | G21: 13 | H21: Tendencias Vengativas | I21: ='RPTA SIGNIFICATIVAS'!C21 -> 2 | J21: ='RPTA SIGNIFICATIVAS'!D21 -> 0.25
A22: 3.1 | B22: Expresivamente Pueril | C22: =APLICACION!D16+APLICACION!D17+APLICACION!D35+APLICACION!D63+APLICACION!D84+APLICACION!D111+APLICACION!D121+APLICACION!D147+APLICACION!D196 -> 0 | D22: =IF(C22=0,'PERCENTIL GROSSMAN'!B12,IF(C22=1,'PERCENTIL GROSSMAN'!D12,IF(C22=2,'PERCENTIL GROSSMAN'!F12,IF(C22=3,'PERCENTIL GROSSMAN'!H12,IF(C22=4,'PERCENTIL GROSSMAN'!J12,IF(C22=5,'PERCENTIL GROSSMAN'!L12,IF(C22=6,'PERCENTIL GROSSMAN'!N12,IF(C22=7,'PERCENTIL GROSSMAN'!P12,IF(C22=8,'PERCENTIL GROSSMAN'!R12,IF(C22=9,'PERCENTIL GROSSMAN'!T12)))))))))) -> 0 | E22: =REPT("g",D22/2)
A23: 3.2 | B23: Interpersonalmente Sumiso | C23: =APLICACION!D38+APLICACION!D72+APLICACION!D174+APLICACION!D181+APLICACION!D185+APLICACION!D197+APLICACION!D206 -> 3 | D23: =IF(C23=0,'PERCENTIL GROSSMAN'!B13,IF(C23=1,'PERCENTIL GROSSMAN'!D13,IF(C23=2,'PERCENTIL GROSSMAN'!F13,IF(C23=3,'PERCENTIL GROSSMAN'!H13,IF(C23=4,'PERCENTIL GROSSMAN'!J13,IF(C23=5,'PERCENTIL GROSSMAN'!L13,IF(C23=6,'PERCENTIL GROSSMAN'!N13,IF(C23=7,'PERCENTIL GROSSMAN'!P13,IF(C23=8,'PERCENTIL GROSSMAN'!R13,IF(C23=9,'PERCENTIL GROSSMAN'!T13)))))))))) -> 60 | E23: =REPT("g",D23/2) -> gggggggggggggggggggggggggggggg
A24: 3.3 | B24: Autoimagen Inepta | C24: =APLICACION!D54+APLICACION!E65+APLICACION!E79+APLICACION!D89+APLICACION!D97+APLICACION!D105+APLICACION!D145+APLICACION!D163+APLICACION!D187 -> 2 | D24: =IF(C24=0,'PERCENTIL GROSSMAN'!B14,IF(C24=1,'PERCENTIL GROSSMAN'!D14,IF(C24=2,'PERCENTIL GROSSMAN'!F14,IF(C24=3,'PERCENTIL GROSSMAN'!H14,IF(C24=4,'PERCENTIL GROSSMAN'!J14,IF(C24=5,'PERCENTIL GROSSMAN'!L14,IF(C24=6,'PERCENTIL GROSSMAN'!N14,IF(C24=7,'PERCENTIL GROSSMAN'!P14,IF(C24=8,'PERCENTIL GROSSMAN'!R14,IF(C24=9,'PERCENTIL GROSSMAN'!T14)))))))))) -> 30 | E24: =REPT("g",D24/2) -> ggggggggggggggg
A25: 4A | B25: Histriónico | D25: =CORRECCION!D21 -> 75 | E25: =REPT("g",D25/2) -> ggggggggggggggggggggggggggggggggggggg
A26: 4A.1 | B26: Expresivamente Dramatico | C26: =APLICACION!D22+APLICACION!D50+APLICACION!D95+APLICACION!D129+APLICACION!D144+APLICACION!D154+APLICACION!D183 -> 1 | D26: =IF(C26=0,'PERCENTIL GROSSMAN'!B15,IF(C26=1,'PERCENTIL GROSSMAN'!D15,IF(C26=2,'PERCENTIL GROSSMAN'!F15,IF(C26=3,'PERCENTIL GROSSMAN'!H15,IF(C26=4,'PERCENTIL GROSSMAN'!J15,IF(C26=5,'PERCENTIL GROSSMAN'!L15,IF(C26=6,'PERCENTIL GROSSMAN'!N15,IF(C26=7,'PERCENTIL GROSSMAN'!P15,IF(C26=8,'PERCENTIL GROSSMAN'!R15,IF(C26=9,'PERCENTIL GROSSMAN'!T15)))))))))) -> 60 | E26: =REPT("g",D26/2) -> gggggggggggggggggggggggggggggg | H26: Respuestas Siginificativas
A27: 4A.2 | B27: Interpersonalmente buscador de Atención | C27: =APLICACION!E18+APLICACION!E27+APLICACION!E36+APLICACION!E38+APLICACION!E38+APLICACION!D42+APLICACION!D58+APLICACION!D96+APLICACION!E151+APLICACION!D166+APLICACION!E207 -> 9 | D27: =IF(C27=0,'PERCENTIL GROSSMAN'!B16,IF(C27=1,'PERCENTIL GROSSMAN'!D16,IF(C27=2,'PERCENTIL GROSSMAN'!F16,IF(C27=3,'PERCENTIL GROSSMAN'!H16,IF(C27=4,'PERCENTIL GROSSMAN'!J16,IF(C27=5,'PERCENTIL GROSSMAN'!L16,IF(C27=6,'PERCENTIL GROSSMAN'!N16,IF(C27=7,'PERCENTIL GROSSMAN'!P16,IF(C27=8,'PERCENTIL GROSSMAN'!R16,IF(C27=9,'PERCENTIL GROSSMAN'!T16)))))))))) -> 93 | E27: =REPT("g",D27/2) -> gggggggggggggggggggggggggggggggggggggggggggggg | G27: 1 | H27: TDAH | I27: =REPT("g",J9*100/5) -> gggggg
A28: 4A.3 | B28: Temperamentalmente Inconstante | C28: =APLICACION!D20+APLICACION!D32+APLICACION!D39+APLICACION!D65+APLICACION!D79+APLICACION!D87+APLICACION!E147+APLICACION!D167+APLICACION!E182+APLICACION!D186+APLICACION!D190 -> 8 | D28: =IF(C28=0,'PERCENTIL GROSSMAN'!B17,IF(C28=1,'PERCENTIL GROSSMAN'!D17,IF(C28=2,'PERCENTIL GROSSMAN'!F17,IF(C28=3,'PERCENTIL GROSSMAN'!H17,IF(C28=4,'PERCENTIL GROSSMAN'!J17,IF(C28=5,'PERCENTIL GROSSMAN'!L17,IF(C28=6,'PERCENTIL GROSSMAN'!N17,IF(C28=7,'PERCENTIL GROSSMAN'!P17,IF(C28=8,'PERCENTIL GROSSMAN'!R17,IF(C28=9,'PERCENTIL GROSSMAN'!T17)))))))))) -> 75 | E28: =REPT("g",D28/2) -> ggggggggggggggggggggggggggggggggggggg | G28: 2 | H28: Espectro Autista | I28: =REPT("g",J10*100/5)
A29: 4B | B29: Tempestuoso | D29: =CORRECCION!D22 -> 80 | E29: =REPT("g",D29/2) -> gggggggggggggggggggggggggggggggggggggggg | G29: 3 | H29: Maltrato Infantil | I29: =REPT("g",J11*100/5) -> gggggggggggggggggggg
A30: 4B.1 | B30: Expresivamente Impetuoso | C30: =APLICACION!D20+APLICACION!D32+APLICACION!D65+APLICACION!D87+APLICACION!D141+APLICACION!D167+APLICACION!D186 -> 7 | D30: =IF(C30=0,'PERCENTIL GROSSMAN'!B18,IF(C30=1,'PERCENTIL GROSSMAN'!D18,IF(C30=2,'PERCENTIL GROSSMAN'!F18,IF(C30=3,'PERCENTIL GROSSMAN'!H18,IF(C30=4,'PERCENTIL GROSSMAN'!J18,IF(C30=5,'PERCENTIL GROSSMAN'!L18,IF(C30=6,'PERCENTIL GROSSMAN'!N18,IF(C30=7,'PERCENTIL GROSSMAN'!P18,IF(C30=8,'PERCENTIL GROSSMAN'!R18,IF(C30=9,'PERCENTIL GROSSMAN'!T18)))))))))) -> 75 | E30: =REPT("g",D30/2) -> ggggggggggggggggggggggggggggggggggggg | G30: 4 | H30: Trastornos de la conducta alimentaria | I30: =REPT("g",J12*100/5)
A31: 4B.2 | B31: Interpersonamente Eufórico | C31: =APLICACION!D17+APLICACION!D22+APLICACION!E38+APLICACION!D42+APLICACION!D58+APLICACION!D96+APLICACION!D129+APLICACION!E161+APLICACION!D166 -> 5 | D31: =IF(C31=0,'PERCENTIL GROSSMAN'!B19,IF(C31=1,'PERCENTIL GROSSMAN'!D19,IF(C31=2,'PERCENTIL GROSSMAN'!F19,IF(C31=3,'PERCENTIL GROSSMAN'!H19,IF(C31=4,'PERCENTIL GROSSMAN'!J19,IF(C31=5,'PERCENTIL GROSSMAN'!L19,IF(C31=6,'PERCENTIL GROSSMAN'!N19,IF(C31=7,'PERCENTIL GROSSMAN'!P19,IF(C31=8,'PERCENTIL GROSSMAN'!R19,IF(C31=9,'PERCENTIL GROSSMAN'!T19)))))))))) -> 70 | E31: =REPT("g",D31/2) -> ggggggggggggggggggggggggggggggggggg | G31: 5 | H31: Falta de Control Emocional | I31: =REPT("g",J13*100/5) -> gg
A32: 4B.3 | B32: Autoimagen Sobreestimada | C32: =APLICACION!E26+APLICACION!D79+APLICACION!E105+APLICACION!E132+APLICACION!D154+APLICACION!E168+APLICACION!E187+APLICACION!E190 -> 7 | D32: =IF(C32=0,'PERCENTIL GROSSMAN'!B20,IF(C32=1,'PERCENTIL GROSSMAN'!D20,IF(C32=2,'PERCENTIL GROSSMAN'!F20,IF(C32=3,'PERCENTIL GROSSMAN'!H20,IF(C32=4,'PERCENTIL GROSSMAN'!J20,IF(C32=5,'PERCENTIL GROSSMAN'!L20,IF(C32=6,'PERCENTIL GROSSMAN'!N20,IF(C32=7,'PERCENTIL GROSSMAN'!P20,IF(C32=8,'PERCENTIL GROSSMAN'!R20,IF(C32=9,'PERCENTIL GROSSMAN'!T20)))))))))) -> 85 | E32: =REPT("g",D32/2) -> gggggggggggggggggggggggggggggggggggggggggg | G32: 6 | H32: Explosiones de Ira | I32: =REPT("g",J14*100/5)
A33: 5 | B33: Narcisista | D33: =CORRECCION!D23 -> 62 | E33: =REPT("g",D33/2) -> ggggggggggggggggggggggggggggggg | G33: 7 | H33: Preocupación por su salud | I33: =REPT("g",J15*100/5)
A34: 5.1 | B34: Interpersonalmente Explotador | C34: =APLICACION!D22+APLICACION!D31+APLICACION!D50+APLICACION!D95+APLICACION!D129+APLICACION!D144+APLICACION!D171+APLICACION!D183+APLICACION!D195 -> 1 | D34: =IF(C34=0,'PERCENTIL GROSSMAN'!B21,IF(C34=1,'PERCENTIL GROSSMAN'!D21,IF(C34=2,'PERCENTIL GROSSMAN'!F21,IF(C34=3,'PERCENTIL GROSSMAN'!H21,IF(C34=4,'PERCENTIL GROSSMAN'!J21,IF(C34=5,'PERCENTIL GROSSMAN'!L21,IF(C34=6,'PERCENTIL GROSSMAN'!N21,IF(C34=7,'PERCENTIL GROSSMAN'!P21,IF(C34=8,'PERCENTIL GROSSMAN'!R21,IF(C34=9,'PERCENTIL GROSSMAN'!T21)))))))))) -> 60 | E34: =REPT("g",D34/2) -> gggggggggggggggggggggggggggggg | G34: 8 | H34: Alienación Interpersonal | I34: =REPT("g",J16*100/5)
A35: 5.2 | B35: Cognitivamente Expansivo | C35: =APLICACION!D20+APLICACION!D79+APLICACION!D87+APLICACION!E105+APLICACION!D154+APLICACION!D166+APLICACION!D167+APLICACION!D186+APLICACION!E190+APLICACION!D197 -> 9 | D35: =IF(C35=0,'PERCENTIL GROSSMAN'!B22,IF(C35=1,'PERCENTIL GROSSMAN'!D22,IF(C35=2,'PERCENTIL GROSSMAN'!F22,IF(C35=3,'PERCENTIL GROSSMAN'!H22,IF(C35=4,'PERCENTIL GROSSMAN'!J22,IF(C35=5,'PERCENTIL GROSSMAN'!L22,IF(C35=6,'PERCENTIL GROSSMAN'!N22,IF(C35=7,'PERCENTIL GROSSMAN'!P22,IF(C35=8,'PERCENTIL GROSSMAN'!R22,IF(C35=9,'PERCENTIL GROSSMAN'!T22)))))))))) -> 85 | E35: =REPT("g",D35/2) -> gggggggggggggggggggggggggggggggggggggggggg | G35: 9 | H35: Abuso de Medicación | I35: =REPT("g",J17*100/5)
A36: 5.3 | B36: Autoimagen Admirable | C36: =APLICACION!D41+APLICACION!D66+APLICACION!D91+APLICACION!D99+APLICACION!D118+APLICACION!D192+APLICACION!D201 -> 1 | D36: =IF(C36=0,'PERCENTIL GROSSMAN'!B23,IF(C36=1,'PERCENTIL GROSSMAN'!D23,IF(C36=2,'PERCENTIL GROSSMAN'!F23,IF(C36=3,'PERCENTIL GROSSMAN'!H23,IF(C36=4,'PERCENTIL GROSSMAN'!J23,IF(C36=5,'PERCENTIL GROSSMAN'!L23,IF(C36=6,'PERCENTIL GROSSMAN'!N23,IF(C36=7,'PERCENTIL GROSSMAN'!P23,IF(C36=8,'PERCENTIL GROSSMAN'!R23,IF(C36=9,'PERCENTIL GROSSMAN'!T23)))))))))) -> 60 | E36: =REPT("g",D36/2) -> gggggggggggggggggggggggggggggg | G36: 10 | H36: Potencial Conducta autodestructiva | I36: =REPT("g",J18*100/5) -> ggg
A37: 6A | B37: Antisocial | D37: =CORRECCION!D24 -> 20 | E37: =REPT("g",D37/2) -> gggggggggg | G37: 11 | H37: Conductas/Tendencias Autolesivas | I37: =REPT("g",J19*100/5)
A38: 6A.1 | B38: Intepersonalmente Responsable | C38: =APLICACION!E22+APLICACION!E50+APLICACION!D95+APLICACION!D115+APLICACION!D171+APLICACION!E183+APLICACION!D195+APLICACION!E200 -> 4 | D38: =IF(C38=0,'PERCENTIL GROSSMAN'!B24,IF(C38=1,'PERCENTIL GROSSMAN'!D24,IF(C38=2,'PERCENTIL GROSSMAN'!F24,IF(C38=3,'PERCENTIL GROSSMAN'!H24,IF(C38=4,'PERCENTIL GROSSMAN'!J24,IF(C38=5,'PERCENTIL GROSSMAN'!L24,IF(C38=6,'PERCENTIL GROSSMAN'!N24,IF(C38=7,'PERCENTIL GROSSMAN'!P24,IF(C38=8,'PERCENTIL GROSSMAN'!R24,IF(C38=9,'PERCENTIL GROSSMAN'!T24)))))))))) -> 75 | E38: =REPT("g",D38/2) -> ggggggggggggggggggggggggggggggggggggg | G38: 12 | H38: Lesión Cerebral | I38: =REPT("g",J20*100/5)
A39: 6A.2 | B39: Autoimagen Autónoma | C39: =APLICACION!D23+APLICACION!D31+APLICACION!E60+APLICACION!E85+APLICACION!D159+APLICACION!D164+APLICACION!D165+APLICACION!E170+APLICACION!D180+APLICACION!E203 -> 3 | D39: =IF(C39=0,'PERCENTIL GROSSMAN'!B25,IF(C39=1,'PERCENTIL GROSSMAN'!D25,IF(C39=2,'PERCENTIL GROSSMAN'!F25,IF(C39=3,'PERCENTIL GROSSMAN'!H25,IF(C39=4,'PERCENTIL GROSSMAN'!J25,IF(C39=5,'PERCENTIL GROSSMAN'!L25,IF(C39=6,'PERCENTIL GROSSMAN'!N25,IF(C39=7,'PERCENTIL GROSSMAN'!P25,IF(C39=8,'PERCENTIL GROSSMAN'!R25,IF(C39=9,'PERCENTIL GROSSMAN'!T25)))))))))) -> 65 | E39: =REPT("g",D39/2) -> gggggggggggggggggggggggggggggggg | G39: 13 | H39: Tendencias Vengativas | I39: =REPT("g",J21*100/5) -> ggggg
A40: 6A.3 | B40: Dinámicas de Irreflexión | C40: =APLICACION!D37+APLICACION!D48+APLICACION!D73+APLICACION!E75+APLICACION!D97+APLICACION!D117+APLICACION!D138+APLICACION!D142+APLICACION!D156 -> 1 | D40: =IF(C40=0,'PERCENTIL GROSSMAN'!B26,IF(C40=1,'PERCENTIL GROSSMAN'!D26,IF(C40=2,'PERCENTIL GROSSMAN'!F26,IF(C40=3,'PERCENTIL GROSSMAN'!H26,IF(C40=4,'PERCENTIL GROSSMAN'!J26,IF(C40=5,'PERCENTIL GROSSMAN'!L26,IF(C40=6,'PERCENTIL GROSSMAN'!N26,IF(C40=7,'PERCENTIL GROSSMAN'!P26,IF(C40=8,'PERCENTIL GROSSMAN'!R26,IF(C40=9,'PERCENTIL GROSSMAN'!T26)))))))))) -> 60 | E40: =REPT("g",D40/2) -> gggggggggggggggggggggggggggggg
A41: 6B | B41: Sádico | D41: =CORRECCION!D25 -> 10 | E41: =REPT("g",D41/2) -> ggggg
A42: 6B.1 | B42: Expresivamente Precipitado | C42: =APLICACION!D21+APLICACION!D23+APLICACION!D77+APLICACION!D78+APLICACION!D100+APLICACION!D115+APLICACION!D164+APLICACION!D165+APLICACION!D171 -> 2 | D42: =IF(C42=0,'PERCENTIL GROSSMAN'!B27,IF(C42=1,'PERCENTIL GROSSMAN'!D27,IF(C42=2,'PERCENTIL GROSSMAN'!F27,IF(C42=3,'PERCENTIL GROSSMAN'!H27,IF(C42=4,'PERCENTIL GROSSMAN'!J27,IF(C42=5,'PERCENTIL GROSSMAN'!L27,IF(C42=6,'PERCENTIL GROSSMAN'!N27,IF(C42=7,'PERCENTIL GROSSMAN'!P27,IF(C42=8,'PERCENTIL GROSSMAN'!R27,IF(C42=9,'PERCENTIL GROSSMAN'!T27)))))))))) -> 40 | E42: =REPT("g",D42/2) -> gggggggggggggggggggg
A43: 6B.2 | B43: Interpersonalmente Desagradable | C43: =APLICACION!D31+APLICACION!D33+APLICACION!D62+APLICACION!D109+APLICACION!D153+APLICACION!E178+APLICACION!D199 -> 2 | D43: =IF(C43=0,'PERCENTIL GROSSMAN'!B28,IF(C43=1,'PERCENTIL GROSSMAN'!D28,IF(C43=2,'PERCENTIL GROSSMAN'!F28,IF(C43=3,'PERCENTIL GROSSMAN'!H28,IF(C43=4,'PERCENTIL GROSSMAN'!J28,IF(C43=5,'PERCENTIL GROSSMAN'!L28,IF(C43=6,'PERCENTIL GROSSMAN'!N28,IF(C43=7,'PERCENTIL GROSSMAN'!P28,IF(C43=8,'PERCENTIL GROSSMAN'!R28,IF(C43=9,'PERCENTIL GROSSMAN'!T28)))))))))) -> 64 | E43: =REPT("g",D43/2) -> gggggggggggggggggggggggggggggggg
A44: 6B.3 | B44: Arquitectura Eruptiva | C44: =APLICACION!D28+APLICACION!D49+APLICACION!D86+APLICACION!D127+APLICACION!D149+APLICACION!D157+APLICACION!D180 -> 0 | D44: =IF(C44=0,'PERCENTIL GROSSMAN'!B29,IF(C44=1,'PERCENTIL GROSSMAN'!D29,IF(C44=2,'PERCENTIL GROSSMAN'!F29,IF(C44=3,'PERCENTIL GROSSMAN'!H29,IF(C44=4,'PERCENTIL GROSSMAN'!J29,IF(C44=5,'PERCENTIL GROSSMAN'!L29,IF(C44=6,'PERCENTIL GROSSMAN'!N29,IF(C44=7,'PERCENTIL GROSSMAN'!P29,IF(C44=8,'PERCENTIL GROSSMAN'!R29,IF(C44=9,'PERCENTIL GROSSMAN'!T29)))))))))) -> 0 | E44: =REPT("g",D44/2)
A45: 7 | B45: Compulsivo | D45: =CORRECCION!D26 -> 49 | E45: =REPT("g",D45/2) -> gggggggggggggggggggggggg
A46: 7.1 | B46: Expresivamente Disciplinado | C46: =APLICACION!D14+APLICACION!D32+APLICACION!D47+APLICACION!D75+APLICACION!E97+APLICACION!E130+APLICACION!D186+APLICACION!D200 -> 6 | D46: =IF(C46=0,'PERCENTIL GROSSMAN'!B30,IF(C46=1,'PERCENTIL GROSSMAN'!D30,IF(C46=2,'PERCENTIL GROSSMAN'!F30,IF(C46=3,'PERCENTIL GROSSMAN'!H30,IF(C46=4,'PERCENTIL GROSSMAN'!J30,IF(C46=5,'PERCENTIL GROSSMAN'!L30,IF(C46=6,'PERCENTIL GROSSMAN'!N30,IF(C46=7,'PERCENTIL GROSSMAN'!P30,IF(C46=8,'PERCENTIL GROSSMAN'!R30,IF(C46=9,'PERCENTIL GROSSMAN'!T30)))))))))) -> 75 | E46: =REPT("g",D46/2) -> ggggggggggggggggggggggggggggggggggggg
A47: 7.2 | B47: Cognitivamente Constreñido | C47: =APLICACION!D35+APLICACION!D56+APLICACION!D63+APLICACION!D64+APLICACION!D111+APLICACION!D140+APLICACION!D143+APLICACION!D147+APLICACION!D149 -> 1 | D47: =IF(C47=0,'PERCENTIL GROSSMAN'!B31,IF(C47=1,'PERCENTIL GROSSMAN'!D31,IF(C47=2,'PERCENTIL GROSSMAN'!F31,IF(C47=3,'PERCENTIL GROSSMAN'!H31,IF(C47=4,'PERCENTIL GROSSMAN'!J31,IF(C47=5,'PERCENTIL GROSSMAN'!L31,IF(C47=6,'PERCENTIL GROSSMAN'!N31,IF(C47=7,'PERCENTIL GROSSMAN'!P31,IF(C47=8,'PERCENTIL GROSSMAN'!R31,IF(C47=9,'PERCENTIL GROSSMAN'!T31)))))))))) -> 9 | E47: =REPT("g",D47/2) -> gggg
...

Sheet CORRECCION
C3: Nombre:
C4: =APLICACION!B10 -> 0
B9: ESCALA DE VALIDEZ | C9: Escalas de Validez | D9: PD
B10: V | C10: Invalidez | D10: ='RESULTADOS '!D10 -> 1 | O10: ='RESULTADOS '!O10:T10 -> válido pero dudable, cuestionable.
B11: W | C11: Inconsistencia | D11: ='RESULTADOS '!D11 -> 7 | O11: ='RESULTADOS '!O11:T11 -> consistente.
B12: X | C12: Sinceridad | D12: ='RESULTADOS '!D12 -> 30 | K12: =APLICACION!G63 -> 26 | O12: ='RESULTADOS '!O12:T12 -> clínicamente interpretable
B13: Y | C13: Deseabilidad Social | D13: ='RESULTADOS '!D13 -> 78 | K13: =APLICACION!G64 -> 18 | O13: ='RESULTADOS '!O13:T13 -> Tendencia a parecer socialmente agradable, moralmente admirable o emocionalmente equilibrado. Tendencia a mostrar una imagen de sí mismo positiva e interesante. Cuanto más alta sea la puntuación, más probable es que el paciente haya ocultado ciertos aspectos de sus dificultades psicológicas o interpersonales.
B14: Z | C14: Devaluación | D14: ='RESULTADOS '!D14 -> 37 | K14: =APLICACION!G65 -> 4 | O14: ='RESULTADOS '!O14:T14 -> Tendencia del sujeto a menospreciarse o subestimarse manifestando más problemas emocionales y perso¬nales de los que un análisis posterior pueda reflejar.
B16: Patrones de Personalidad | D16: PE | H16: PERCENTIL | L16: PD
B17: 1 | C17: Esquizoide | D17: =VLOOKUP(L17,TABLAPD,E17,FALSE) -> 40 | E17: 3 | G17: 2 | H17: =IFERROR(VLOOKUP(D17,TABLAPER,G17,FALSE),"") -> 31 | L17: =APLICACION!F17 -> 6 | O17: =IF(D17<=60,"No presenta",IF(D17>=85,"Trastornos Críticos",IF(D17>=75,"Patrones menos adaptativos y Trastornos","Categoría de Riesgo"))) -> No presenta
B18: 2A | C18: Evitativo | D18: =VLOOKUP(L18,TABLAPD,E18,FALSE) -> 6 | E18: 4 | G18: 3 | H18: =IFERROR(VLOOKUP(D18,TABLAPER,G18,FALSE),"") -> 5 | L18: =APLICACION!F18 -> 1 | O18: =IF(D18<=60,"No presenta",IF(D18>=85,"Trastornos Críticos",IF(D18>=75,"Patrones menos adaptativos y Trastornos","Categoría de Riesgo"))) -> No presenta
B19: 2B | C19: Melancólico | D19: =VLOOKUP(L19,TABLAPD,E19,FALSE) -> 30 | E19: 5 | G19: 4 | H19: =IFERROR(VLOOKUP(D19,TABLAPER,G19,FALSE),"") -> 28 | L19: =APLICACION!F19 -> 6 | O19: =IF(D19<=60,"No presenta",IF(D19>=85,"Trastornos Críticos",IF(D19>=75,"Patrones menos adaptativos y Trastornos","Categoría de Riesgo"))) -> No presenta
B20: 3 | C20: Dependiente | D20: =VLOOKUP(L20,TABLAPD,E20,FALSE) -> 36 | E20: 6 | G20: 5 | H20: =IFERROR(VLOOKUP(D20,TABLAPER,G20,FALSE),"") -> 25 | L20: =APLICACION!F20 -> 6 | O20: =IF(D20<=60,"No presenta",IF(D20>=85,"Trastornos Críticos",IF(D20>=75,"Patrones menos adaptativos y Trastornos","Categoría de Riesgo"))) -> No presenta
B21: 4A | C21: Histriónico | D21: =VLOOKUP(L21,TABLAPD,E21,FALSE) -> 75 | E21: 7 | G21: 6 | H21: =IFERROR(VLOOKUP(D21,TABLAPER,G21,FALSE),"") -> 83 | L21: =APLICACION!F21 -> 15 | O21: =IF(D21<=60,"No presenta",IF(D21>=85,"Trastornos Críticos",IF(D21>=75,"Patrones menos adaptativos y Trastornos","Categoría de Riesgo"))) -> Patrones menos adaptativos y Trastornos
B22: 4B | C22: Tempestuoso | D22: =VLOOKUP(L22,TABLAPD,E22,FALSE) -> 80 | E22: 8 | G22: 7 | H22: =IFERROR(VLOOKUP(D22,TABLAPER,G22,FALSE),"") -> 93 | L22: =APLICACION!F22 -> 22 | O22: =IF(D22<=60,"No presenta",IF(D22>=85,"Trastornos Críticos",IF(D22>=75,"Patrones menos adaptativos y Trastornos","Categoría de Riesgo"))) -> Patrones menos adaptativos y Trastornos
B23: 5 | C23: Narcisista | D23: =VLOOKUP(L23,TABLAPD,E23,FALSE) -> 62 | E23: 9 | G23: 8 | H23: =IFERROR(VLOOKUP(D23,TABLAPER,G23,FALSE),"") -> 56 | L23: =APLICACION!F23 -> 6 | O23: =IF(D23<=60,"No presenta",IF(D23>=85,"Trastornos Críticos",IF(D23>=75,"Patrones menos adaptativos y Trastornos","Categoría de Riesgo"))) -> Categoría de Riesgo
B24: 6A | C24: Antisocial | D24: =VLOOKUP(L24,TABLAPD,E24,FALSE) -> 20 | E24: 10 | G24: 9 | H24: =IFERROR(VLOOKUP(D24,TABLAPER,G24,FALSE),"") -> 25 | L24: =APLICACION!F24 -> 1 | O24: =IF(D24<=60,"No presenta",IF(D24>=85,"Trastornos Críticos",IF(D24>=75,"Patrones menos adaptativos y Trastornos","Categoría de Riesgo"))) -> No presenta
B25: 6B | C25: Sádico | D25: =VLOOKUP(L25,TABLAPD,E25,FALSE) -> 10 | E25: 11 | G25: 10 | H25: =IFERROR(VLOOKUP(D25,TABLAPER,G25,FALSE),"") -> 13 | L25: =APLICACION!F25 -> 1 | O25: =IF(D25<=60,"No presenta",IF(D25>=85,"Trastornos Críticos",IF(D25>=75,"Patrones menos adaptativos y Trastornos","Categoría de Riesgo"))) -> No presenta
B26: 7 | C26: Compulsivo | D26: =VLOOKUP(L26,TABLAPD,E26,FALSE) -> 49 | E26: 12 | G26: 11 | H26: =IFERROR(VLOOKUP(D26,TABLAPER,G26,FALSE),"") -> 26 | L26: =APLICACION!F26 -> 13 | O26: =IF(D26<=60,"No presenta",IF(D26>=85,"Trastornos Críticos",IF(D26>=75,"Patrones menos adaptativos y Trastornos","Categoría de Riesgo"))) -> No presenta
B27: 8A | C27: Negativista | D27: =VLOOKUP(L27,TABLAPD,E27,FALSE) -> 60 | E27: 13 | G27: 12 | H27: =IFERROR(VLOOKUP(D27,TABLAPER,G27,FALSE),"") -> 48 | L27: =APLICACION!F27 -> 9 | O27: =IF(D27<=60,"No presenta",IF(D27>=85,"Trastornos Críticos",IF(D27>=75,"Patrones menos adaptativos y Trastornos","Categoría de Riesgo"))) -> No presenta
B28: 8B | C28: Masoquista | D28: =VLOOKUP(L28,TABLAPD,E28,FALSE) -> 38 | E28: 14 | G28: 13 | H28: =IFERROR(VLOOKUP(D28,TABLAPER,G28,FALSE),"") -> 33 | L28: =APLICACION!F28 -> 5 | O28: =IF(D28<=60,"No presenta",IF(D28>=85,"Trastornos Críticos",IF(D28>=75,"Patrones menos adaptativos y Trastornos","Categoría de Riesgo"))) -> No presenta
B29: Patologías Graves Personalidad | D29: PE | H29: PERCENTIL | L29: PD | O29: =IF(D29<=60,"No presenta",IF(D29>=85,"Trastornos Críticos",IF(D29>=75,"Patrones menos adaptativos y Trastornos","Categoría de Riesgo"))) -> Trastornos Críticos
B30: S | C30: Esquizotípico | D30: =VLOOKUP(L30,TABLAPD,E30,FALSE) -> 12 | E30: 15 | G30: 14 | H30: =IFERROR(VLOOKUP(D30,TABLAPER,G30,FALSE),"") -> 14 | L30: =APLICACION!F29 -> 2 | O30: =IF(D30<=60,"No presenta",IF(D30>=85,"Trastornos Críticos",IF(D30>=75,"Patrones menos adaptativos y Trastornos","Categoría de Riesgo"))) -> No presenta
B31: C | C31: Límite | D31: =VLOOKUP(L31,TABLAPD,E31,FALSE) -> 45 | E31: 16 | G31: 15 | H31: =IFERROR(VLOOKUP(D31,TABLAPER,G31,FALSE),"") -> 40 | L31: =APLICACION!F30 -> 6 | O31: =IF(D31<=60,"No presenta",IF(D31>=85,"Trastornos Críticos",IF(D31>=75,"Patrones menos adaptativos y Trastornos","Categoría de Riesgo"))) -> No presenta
B32: P | C32: Paranoide | D32: =VLOOKUP(L32,TABLAPD,E32,FALSE) -> 66 | E32: 17 | G32: 16 | H32: =IFERROR(VLOOKUP(D32,TABLAPER,G32,FALSE),"") -> 62 | L32: =APLICACION!F31 -> 9 | O32: =IF(D32<=60,"No presenta",IF(D32>=85,"Trastornos Críticos",IF(D32>=75,"Patrones menos adaptativos y Trastornos","Categoría de Riesgo"))) -> Categoría de Riesgo
O33: =IF(D33<=60,"No presenta",IF(D33>=85,"Trastornos Críticos",IF(D33>=75,"Patrones menos adaptativos y Trastornos","Categoría de Riesgo"))) -> No presenta
B34: Sindromes Clínicos | D34: PE | H34: PERCENTIL | L34: PD | O34: =IF(D34<=60,"No presenta",IF(D34>=85,"Trastornos Críticos",IF(D34>=75,"Patrones menos adaptativos y Trastornos","Categoría de Riesgo"))) -> Trastornos Críticos
B35: A | C35: Ansiedad Generalizada | D35: =VLOOKUP(L35,TABLAPD,E35,FALSE) -> 15 | E35: 18 | G35: 17 | H35: =IFERROR(VLOOKUP(D35,TABLAPER,G35,FALSE),"") -> 14 | L35: =APLICACION!F35 -> 2 | O35: =IF(D35<=60,"No presenta",IF(D35>=85,"Trastornos Críticos",IF(D35>=75,"Patrones menos adaptativos y Trastornos","Categoría de Riesgo"))) -> No presenta
B36: H | C36: Síntomas Somáticos | D36: =VLOOKUP(L36,TABLAPD,E36,FALSE) -> 0 | E36: 19 | G36: 18 | H36: =IFERROR(VLOOKUP(D36,TABLAPER,G36,FALSE),"") -> 11 | L36: =APLICACION!F36 -> 0 | O36: =IF(D36<=60,"No presenta",IF(D36>=85,"Trastornos Críticos",IF(D36>=75,"Patrones menos adaptativos y Trastornos","Categoría de Riesgo"))) -> No presenta
B37: N | C37: Espectro Bípolar | D37: =VLOOKUP(L37,TABLAPD,E37,FALSE) -> 30 | E37: 20 | G37: 19 | H37: =IFERROR(VLOOKUP(D37,TABLAPER,G37,FALSE),"") -> 22 | L37: =APLICACION!F37 -> 3 | O37: =IF(D37<=60,"No presenta",IF(D37>=85,"Trastornos Críticos",IF(D37>=75,"Patrones menos adaptativos y Trastornos","Categoría de Riesgo"))) -> No presenta
B38: D | C38: Depresión Persistente | D38: =VLOOKUP(L38,TABLAPD,E38,FALSE) -> 30 | E38: 21 | G38: 20 | H38: =IFERROR(VLOOKUP(D38,TABLAPER,G38,FALSE),"") -> 28 | L38: =APLICACION!F38 -> 6 | O38: =IF(D38<=60,"No presenta",IF(D38>=85,"Trastornos Críticos",IF(D38>=75,"Patrones menos adaptativos y Trastornos","Categoría de Riesgo"))) -> No presenta
B39: B | C39: Consumo de Alcohol | D39: =VLOOKUP(L39,TABLAPD,E39,FALSE) -> 0 | E39: 22 | G39: 21 | H39: =IFERROR(VLOOKUP(D39,TABLAPER,G39,FALSE),"") -> 34 | L39: =APLICACION!F39 -> 0 | O39: =IF(D39<=60,"No presenta",IF(D39>=85,"Trastornos Críticos",IF(D39>=75,"Patrones menos adaptativos y Trastornos","Categoría de Riesgo"))) -> No presenta
B40: T | C40: Consumo de Drogas | D40: =VLOOKUP(L40,TABLAPD,E40,FALSE) -> 0 | E40: 23 | G40: 22 | H40: =IFERROR(VLOOKUP(D40,TABLAPER,G40,FALSE),"") -> 24 | L40: =APLICACION!F40 -> 0 | O40: =IF(D40<=60,"No presenta",IF(D40>=85,"Trastornos Críticos",IF(D40>=75,"Patrones menos adaptativos y Trastornos","Categoría de Riesgo"))) -> No presenta
B41: R | C41: Estrés Postraumático | D41: =VLOOKUP(L41,TABLAPD,E41,FALSE) -> 48 | E41: 24 | G41: 23 | H41: =IFERROR(VLOOKUP(D41,TABLAPER,G41,FALSE),"") -> 42 | L41: =APLICACION!F41 -> 4 | O41: =IF(D41<=60,"No presenta",IF(D41>=85,"Trastornos Críticos",IF(D41>=75,"Patrones menos adaptativos y Trastornos","Categoría de Riesgo"))) -> No presenta
B42: SS | C42: Espectro Esquizofrénico | D42: =VLOOKUP(L42,TABLAPD,E42,FALSE) -> 40 | E42: 25 | G42: 24 | H42: =IFERROR(VLOOKUP(D42,TABLAPER,G42,FALSE),"") -> 33 | L42: =APLICACION!F42 -> 6 | O42: =IF(D42<=60,"No presenta",IF(D42>=85,"Trastornos Críticos",IF(D42>=75,"Patrones menos adaptativos y Trastornos","Categoría de Riesgo"))) -> No presenta
B43: CC | C43: Depresión Mayor | D43: =VLOOKUP(L43,TABLAPD,E43,FALSE) -> 51 | E43: 26 | G43: 25 | H43: =IFERROR(VLOOKUP(D43,TABLAPER,G43,FALSE),"") -> 46 | L43: =APLICACION!F43 -> 6 | O43: =IF(D43<=60,"No presenta",IF(D43>=85,"Trastornos Críticos",IF(D43>=75,"Patrones menos adaptativos y Trastornos","Categoría de Riesgo"))) -> No presenta
B44: PP | C44: Delirante | D44: =VLOOKUP(L44,TABLAPD,E44,FALSE) -> 60 | E44: 27 | G44: 26 | H44: =IFERROR(VLOOKUP(D44,TABLAPER,G44,FALSE),"") -> 51 | L44: =APLICACION!F44 -> 2 | O44: =IF(D44<=60,"No presenta",IF(D44>=85,"Trastornos Críticos",IF(D44>=75,"Patrones menos adaptativos y Trastornos","Categoría de Riesgo"))) -> No presenta

Sheet RPTA SIGNIFICATIVAS
A8: Respuestas Siginificativas | C8: PD | D8: %
A9: 1 | B9: TDAH | C9: =APLICACION!D68+APLICACION!D75+APLICACION!D89+APLICACION!D94+APLICACION!D104+APLICACION!D120 -> 2 | D9: =((C9/F9)) -> 0.33333333 | F9: 6
A10: 2 | B10: Espectro Autista | C10: =APLICACION!D104+APLICACION!D131+APLICACION!D150+APLICACION!D175+APLICACION!D177+APLICACION!D191+APLICACION!D202 -> 0 | D10: =((C10/F10)) -> 0 | F10: 7
A11: 3 | B11: Maltrato Infantil | C11: =APLICACION!D59+APLICACION!D169 -> 2 | D11: =((C11/F11)) -> 1 | F11: 2
A12: 4 | B12: Trastornos de la conducta alimentaria | C12: =APLICACION!D81+APLICACION!D98+APLICACION!D114+APLICACION!D198 -> 0 | D12: =((C12/F12)) -> 0 | F12: 4
A13: 5 | B13: Falta de Control Emocional | C13: =APLICACION!D39+APLICACION!D48+APLICACION!D57+APLICACION!D68+APLICACION!D84+APLICACION!D92+APLICACION!D139+APLICACION!D189 -> 1 | D13: =((C13/F13)) -> 0.125 | F13: 8
A14: 6 | B14: Explosiones de Ira | C14: =APLICACION!D23+APLICACION!D86+APLICACION!D127+APLICACION!D157+APLICACION!D180+APLICACION!D203 -> 0 | D14: =((C14/F14)) -> 0 | F14: 6
A15: 7 | B15: Preocupación por su salud | C15: =APLICACION!D19+APLICACION!D53+APLICACION!D69+APLICACION!D125+APLICACION!D132+APLICACION!D158 -> 0 | D15: =((C15/F15)) -> 0 | F15: 6
A16: 8 | B16: Alienación Interpersonal | C16: =APLICACION!D16+APLICACION!D116+APLICACION!D194+APLICACION!D202 -> 0 | D16: =((C16/F16)) -> 0 | F16: 4
A17: 9 | B17: Abuso de Medicación | C17: =APLICACION!D136+APLICACION!D188 -> 0 | D17: =((C17/F17)) -> 0 | F17: 2
A18: 10 | B18: Potencial Conducta autodestructiva | C18: =APLICACION!D26+APLICACION!D44+APLICACION!D46+APLICACION!D51+APLICACION!D71+APLICACION!D90+APLICACION!D113+APLICACION!D119+APLICACION!D126+APLICACION!D138+APLICACION!D163+APLICACION!D176 -> 2 | D18: =((C18/F18)) -> 0.16666667 | F18: 12
A19: 11 | B19: Conductas/Tendencias Autolesivas | C19: =APLICACION!D52+APLICACION!D193 -> 0 | D19: =((C19/F19)) -> 0 | F19: 2
A20: 12 | B20: Lesión Cerebral | C20: =APLICACION!D67+APLICACION!D122 -> 0 | D20: =((C20/F20)) -> 0 | F20: 2
A21: 13 | B21: Tendencias Vengativas | C21: =APLICACION!D34+APLICACION!D49+APLICACION!D112+APLICACION!D115+APLICACION!D148+APLICACION!D179+APLICACION!D190+APLICACION!D204 -> 2 | D21: =((C21/F21)) -> 0.25 | F21: 8

Sheet Interpretacion
E6: =APLICACION!B9 -> Nombre :Estefania Milagros Negron Huapaya
A10: Interpretacion
A12: ='Interpretacion '!A12:G12 -> La escala V señala que sus respuestas son válido pero dudable, cuestionable.
A13: ='Interpretacion '!A13:G13 -> La escala W señala que sus respuestas son consistente.
A14: ='Interpretacion '!A14:G14 -> La escala X señala que sus respuestas son clínicamente interpretable
A15: ='Interpretacion '!A15:G15 -> La escala Y señala que Tendencia a parecer socialmente agradable, moralmente admirable o emocionalmente equilibrado. Tendencia a mostrar una imagen de sí mismo positiva e interesante. Cuanto más alta sea la puntuación, más probable es que el paciente haya ocultado ciertos aspectos de sus dificultades psicológicas o interpersonales.
A16: ='Interpretacion '!A16:G16 -> La escala Z señala que trata deTendencia del sujeto a menospreciarse o subestimarse manifestando más problemas emocionales y perso¬nales de los que un análisis posterior pueda reflejar.
A19: ='Interpretacion '!A19:G19 -> En los patrones de la escala clínica de personalidad presenta
A20: ='Interpretacion '!A20:G20
A21: ='Interpretacion '!A21:G21
A22: ='Interpretacion '!A22:G22
A23: ='Interpretacion '!A23:G23
A24: ='Interpretacion '!A24:G24 -> Histriónico presenta Patrones menos adaptativos y Trastornos Se caracteriza por Los sujetos histriónicos, al igual que los dependientes, recurren a los demás, pero maximizan la atención y los favores que reciben, manipulando los hechos de una forma superficial y entusiasta. Su comportamiento social inteligente y a menudo ingenioso transmite confianza y seguridad en sí mismo; sin embargo, debajo de esta apariencia, subyace el miedo a la autonomía real y la necesidad de recibir señales recurrentes de aceptación y aprobación casi constantemente.
A25: ='Interpretacion '!A25:G25 -> Tempestuoso presenta Patrones menos adaptativos y Trastornos Se caracteriza por Los sujetos tempestuosos son muy alegres y animados, pero su persistente euforia, entrometimiento y vo¬lubilidad puede resultar irritante para los demás. Aunque son apasionados y entusiastas, se aburren con demasiada facilidad y carecen de los recursos y la regularidad necesarios para llevar a término sus objetivos y planes. Sin control, su conducta puede llegar a ser más extrema, temeraria y errática. Con bastante fre¬cuencia, este patrón tipo maníaco, puede conducir al agotamiento depresivo. De todo ello resulta un patrón de conducta impredecible, de pensamiento disperso y de acciones y estados de ánimo impetuosos e impul¬sivos, interrumpidos por arrebatos de ira momentánea y ansiedad temerosa.
... A47: ='Interpretacion '!A47:G47

Sheet Interpretacion 
R5: inferior a 7 o superior a 114, el protocolo debe considerarse inválido.
R6: Tendencia a parecer socialmente agradable, moralmente admirable o emocionalmente equilibrado. Tendencia a mostrar una imagen de sí mismo positiva e interesante. Cuanto más alta sea la puntuación, más probable es que el paciente haya ocultado ciertos aspectos de sus dificultades psicológicas o interpersonales.
A7: =CORRECCION!C4 -> 0 | N7: ESCALA DE VALIDEZ | O7: Escalas de Validez | R7: Tendencia del sujeto a menospreciarse o subestimarse manifestando más problemas emocionales y perso¬nales de los que un análisis posterior pueda reflejar.
J8: La escala V señala que sus respuestas son | N8: V | O8: Invalidez | P8: =CORRECCION!D10 -> 1 | Q8: =IF(P8=0,"100% válida.",IF(P8=1,"válido pero dudable, cuestionable.","prueba no tiene valor alguno, invalida.")) -> válido pero dudable, cuestionable. | R8: =Q8 -> válido pero dudable, cuestionable.
J9: La escala W señala que sus respuestas son | N9: W | O9: Inconsistencia | P9: =CORRECCION!D11 -> 7 | Q9: =IF(P9>18,"cuestionables o inválidos por posibles respuestas aleatorias.","consistente.") -> consistente. | R9: =Q9 -> consistente.
A10: Interpretacion | J10: La escala X señala que sus respuestas son | N10: X | O10: Sinceridad | P10: =CORRECCION!D12 -> 30 | Q10: =IF(P10<6,"el protocolo debe considerarse inválido.",IF(P10>113,"el protocolo debe considerarse inválido.","clínicamente interpretable")) -> clínicamente interpretable | R10: =Q10 -> clínicamente interpretable
J11: La escala Y señala que | N11: Y | O11: Deseabilidad Social | P11: 75 | Q11: =IF(P11<75,"1","2") -> 2 | R11: =IF(Q11="1","se muestra revelador, abierto y expresivo en sus respuestas.",R6) -> Tendencia a parecer socialmente agradable, moralmente admirable o emocionalmente equilibrado. Tendencia a mostrar una imagen de sí mismo positiva e interesante. Cuanto más alta sea la puntuación, más probable es que el paciente haya ocultado ciertos aspectos de sus dificultades psicológicas o interpersonales.
A12: =CONCATENATE(J8,R8) -> La escala V señala que sus respuestas son válido pero dudable, cuestionable. | J12: La escala Z señala que trata de | N12: Z | O12: Devaluación | P12: 76 | Q12: =IF(P12<75,"1","2") -> 2 | R12: =IF(Q12="1","tiende a presentarse tal como se ve a sí mismo, sin ocultar aquello que le parece importante sobre sus sentimientos, emociones y comportamientos.",R7) -> Tendencia del sujeto a menospreciarse o subestimarse manifestando más problemas emocionales y perso¬nales de los que un análisis posterior pueda reflejar.
A13: =CONCATENATE(J9,R9) -> La escala W señala que sus respuestas son consistente.
A14: =CONCATENATE(J10,R10) -> La escala X señala que sus respuestas son clínicamente interpretable | I14: En los patrones de la escala clínica de personalidad presenta | N14: Patrones de Personalidad
A15: =CONCATENATE(J11,R11) -> La escala Y señala que Tendencia a parecer socialmente agradable, moralmente admirable o emocionalmente equilibrado. Tendencia a mostrar una imagen de sí mismo positiva e interesante. Cuanto más alta sea la puntuación, más probable es que el paciente haya ocultado ciertos aspectos de sus dificultades psicológicas o interpersonales. | I15: =IF(R15=1,J15," ") | J15: =CONCATENATE(O15," presenta ",Q15, "Se caracteriza por ",S15) -> Esquizoide presenta No presenta Se caracteriza por | N15: 1 | O15: Esquizoide | P15: =CORRECCION!D17 -> 40 | Q15: =IF(P15<=60,"No presenta ",IF(P15>=85,"Trastornos Críticos ",IF(P15>=75,"Patrones menos adaptativos y Trastornos ","Categoría de Riesgo "))) -> No presenta | R15: =IF(P15<=60,"0",1) -> 0 | S15: =IF(R15=1,V15," ") | V15: Destacan por su falta de deseo e incapacidad de sentir placer o dolor intenso, indiferentes a las relaciones sociales, con necesidades afectivas mínimas.
A16: =CONCATENATE(J12,R12) -> La escala Z señala que trata deTendencia del sujeto a menospreciarse o subestimarse manifestando más problemas emocionales y perso¬nales de los que un análisis posterior pueda reflejar. | I16: =IF(R16=1,J16," ") | J16: =CONCATENATE(O16," presenta ",Q16, "Se caracteriza por ",S16) -> Evitativo presenta No presenta Se caracteriza por | N16: 2A | O16: Evitativo | P16: =CORRECCION!D18 -> 6 | Q16: =IF(P16<=60,"No presenta ",IF(P16>=85,"Trastornos Críticos ",IF(P16>=75,"Patrones menos adaptativos y Trastornos ","Categoría de Riesgo "))) -> No presenta | R16: =IF(P16<=60,"0",1) -> 0 | S16: =IF(R16=1,V16," ") | V16: Los sujetos evitativos experimentan pocos refuerzos positivos procedentes de sí mismos o de los demás, siempre están alerta, preparados para distanciarse de las experiencias dolorosas o negativas de la vida. Su estrategia adaptative refleja miedo y desconfianza hacia los demás. Mantienen una vigilancia constante para evitar que su anhelo de afecto resulte en la repetición del dolor y la angustia que han experimentado con otras personas. A pesar de sus deseos de relacionarse con los demás, han aprendido que es mejor negar estos sentimientos y mantener la distancia interpersonal necesaria
I17: =IF(R17=1,J17," ") | J17: =CONCATENATE(O17," presenta ",Q17, "Se caracteriza por ",S17) -> Melancólico presenta No presenta Se caracteriza por | N17: 2B | O17: Melancólico | P17: =CORRECCION!D19 -> 30 | Q17: =IF(P17<=60,"No presenta ",IF(P17>=85,"Trastornos Críticos ",IF(P17>=75,"Patrones menos adaptativos y Trastornos ","Categoría de Riesgo "))) -> No presenta | R17: =IF(P17<=60,"0",1) -> 0 | S17: =IF(R17=1,V17," ") | V17: A diferencia de los sujetos esquizoides y de los evitativos, los sujetos melancólicos experimentan el dolor como un estado permanente en el que el placer ya no se considera posible. Algunos individuos melancólicos pueden tener una predisposición biológica o química hacia el pesimismo y el desánimo, mientras que otros muestran un estilo de desesperanza ante las pérdidas importantes determinado por la experiencia. El estilo de carácter melancólico puede verse determinado por el hecho de pertenecer a una familia muy triste o des¬animada, estar en un entorno sin interés y tener una perspectiva sin esperanzas.
I18: =IF(R18=1,J18," ") | J18: =CONCATENATE(O18," presenta ",Q18, "Se caracteriza por ",S18) -> Dependiente presenta No presenta Se caracteriza por | N18: 3 | O18: Dependiente | P18: =CORRECCION!D20 -> 36 | Q18: =IF(P18<=60,"No presenta ",IF(P18>=85,"Trastornos Críticos ",IF(P18>=75,"Patrones menos adaptativos y Trastornos ","Categoría de Riesgo "))) -> No presenta | R18: =IF(P18<=60,"0",1) -> 0 | S18: =IF(R18=1,V18," ") | V18: Los sujetos dependientes destacan por su falta de iniciativa y autonomía y han aprendido no solo a recurrir a los demás para obtener afecto, cuidados y seguridad, sino también a esperar pasivamente a que sean ellos quienes los dirijan. Se caracterizan por buscar relaciones en las que puedan apoyarse para conseguir afecto y orientación; y han aprendido que es más cómodo asumir un rol pasivo en las relaciones interpersonales, aceptar las atenciones y el apoyo que puedan encontrar, y someterse voluntariamente a los deseos de los demás a fin de conservar su afecto.
A19: =I14 -> En los patrones de la escala clínica de personalidad presenta | I19: =IF(R19=1,J19," ") -> Histriónico presenta Patrones menos adaptativos y Trastornos Se caracteriza por Los sujetos histriónicos, al igual que los dependientes, recurren a los demás, pero maximizan la atención y los favores que reciben, manipulando los hechos de una forma superficial y entusiasta. Su comportamiento social inteligente y a menudo ingenioso transmite confianza y seguridad en sí mismo; sin embargo, debajo de esta apariencia, subyace el miedo a la autonomía real y la necesidad de recibir señales recurrentes de aceptación y aprobación casi constantemente. | J19: =CONCATENATE(O19," presenta ",Q19, "Se caracteriza por ",S19) -> Histriónico presenta Patrones menos adaptativos y Trastornos Se caracteriza por Los sujetos histriónicos, al igual que los dependientes, recurren a los demás, pero maximizan la atención y los favores que reciben, manipulando los hechos de una forma superficial y entusiasta. Su comportamiento social inteligente y a menudo ingenioso transmite confianza y seguridad en sí mismo; sin embargo, debajo de esta apariencia, subyace el miedo a la autonomía real y la necesidad de recibir señales recurrentes de aceptación y aprobación casi constantemente. | N19: 4A | O19: Histriónico | P19: =CORRECCION!D21 -> 75 | Q19: =IF(P19<=60,"No presenta ",IF(P19>=85,"Trastornos Críticos ",IF(P19>=75,"Patrones menos adaptativos y Trastornos ","Categoría de Riesgo "))) -> Patrones menos adaptativos y Trastornos | R19: =IF(P19<=60,"0",1) -> 1 | S19: =IF(R19=1,V19," ") -> Los sujetos histriónicos, al igual que los dependientes, recurren a los demás, pero maximizan la atención y los favores que reciben, manipulando los hechos de una forma superficial y entusiasta. Su comportamiento social inteligente y a menudo ingenioso transmite confianza y seguridad en sí mismo; sin embargo, debajo de esta apariencia, subyace el miedo a la autonomía real y la necesidad de recibir señales recurrentes de aceptación y aprobación casi constantemente. | V19: Los sujetos histriónicos, al igual que los dependientes, recurren a los demás, pero maximizan la atención y los favores que reciben, manipulando los hechos de una forma superficial y entusiasta. Su comportamiento social inteligente y a menudo ingenioso transmite confianza y seguridad en sí mismo; sin embargo, debajo de esta apariencia, subyace el miedo a la autonomía real y la necesidad de recibir señales recurrentes de aceptación y aprobación casi constantemente.
